Traceback (most recent call last):
  File "C:\Users\phill\AppData\Local\Programs\Python\Python37-32\lib\site-packages\urllib3\connectionpool.py", line 591, in urlopen
    conn = self._get_conn(timeout=pool_timeout)
  File "C:\Users\phill\AppData\Local\Programs\Python\Python37-32\lib\site-packages\urllib3\connectionpool.py", line 249, in _get_conn
    return conn or self._new_conn()
  File "C:\Users\phill\AppData\Local\Programs\Python\Python37-32\lib\site-packages\urllib3\connectionpool.py", line 818, in _new_conn
    raise SSLError("Can't connect to HTTPS URL because the SSL "
urllib3.exceptions.SSLError: Can't connect to HTTPS URL because the SSL module is not available.

During handling of the above exception, another exception occurred:

Traceback (most recent call last):
  File "C:\Users\phill\PycharmProjects\RedScientific\Companion\For_setup\Build 0.3\version_checker.py", line 34, in get_latest_version
    r = mgr.request("GET", version_url)
  File "C:\Users\phill\AppData\Local\Programs\Python\Python37-32\lib\site-packages\urllib3\request.py", line 68, in request
    **urlopen_kw)
  File "C:\Users\phill\AppData\Local\Programs\Python\Python37-32\lib\site-packages\urllib3\request.py", line 89, in request_encode_url
    return self.urlopen(method, url, **extra_kw)
  File "C:\Users\phill\AppData\Local\Programs\Python\Python37-32\lib\site-packages\urllib3\poolmanager.py", line 326, in urlopen
    response = conn.urlopen(method, u.request_uri, **kw)
  File "C:\Users\phill\AppData\Local\Programs\Python\Python37-32\lib\site-packages\urllib3\connectionpool.py", line 670, in urlopen
    **response_kw)
  File "C:\Users\phill\AppData\Local\Programs\Python\Python37-32\lib\site-packages\urllib3\connectionpool.py", line 670, in urlopen
    **response_kw)
  File "C:\Users\phill\AppData\Local\Programs\Python\Python37-32\lib\site-packages\urllib3\connectionpool.py", line 670, in urlopen
    **response_kw)
  File "C:\Users\phill\AppData\Local\Programs\Python\Python37-32\lib\site-packages\urllib3\connectionpool.py", line 641, in urlopen
    _stacktrace=sys.exc_info()[2])
  File "C:\Users\phill\AppData\Local\Programs\Python\Python37-32\lib\site-packages\urllib3\util\retry.py", line 399, in increment
    raise MaxRetryError(_pool, url, error or ResponseError(cause))
urllib3.exceptions.MaxRetryError: HTTPSConnectionPool(host='raw.githubusercontent.com', port=443): Max retries exceeded with url: /redscientific/CompanionApp/master/Version.txt (Caused by SSLError("Can't connect to HTTPS URL because the SSL module is not available."))
